2022-07-17 10:41:19,764:DEBUG:certbot._internal.main:certbot version: 1.22.0
2022-07-17 10:41:19,764:DEBUG:certbot._internal.main:Location of certbot entry point: /usr/local/bin/certbot
2022-07-17 10:41:19,764:DEBUG:certbot._internal.main:Arguments: ['webroot', '-w', '/acme-challenge', '-d', 'council-vote.42heilbronn.de', '-m', 'radelwar@student.42heilbronn.de', '--agree-tos', '--no-eff-email']
2022-07-17 10:41:19,764:DEBUG:certbot._internal.main:Discovered plugins: PluginsRegistry(PluginEntryPoint#manual,PluginEntryPoint#null,PluginEntryPoint#standalone,PluginEntryPoint#webroot)
2022-07-17 10:41:19,775:DEBUG:certbot._internal.log:Exiting abnormally:
Traceback (most recent call last):
  File "/usr/local/bin/certbot", line 33, in <module>
    sys.exit(load_entry_point('certbot', 'console_scripts', 'certbot')())
  File "/opt/certbot/src/certbot/certbot/main.py", line 19, in main
    return internal_main.main(cli_args)
  File "/opt/certbot/src/certbot/certbot/_internal/main.py", line 1604, in main
    args = cli.prepare_and_parse_args(plugins, cli_args)
  File "/opt/certbot/src/certbot/certbot/_internal/cli/__init__.py", line 452, in prepare_and_parse_args
    return helpful.parse_args()
  File "/opt/certbot/src/certbot/certbot/_internal/cli/helpful.py", line 182, in parse_args
    parsed_args = self.parser.parse_args(self.args)
  File "/usr/local/lib/python3.8/site-packages/configargparse.py", line 468, in parse_args
    args, argv = self.parse_known_args(
  File "/usr/local/lib/python3.8/site-packages/configargparse.py", line 650, in parse_known_args
    namespace, unknown_args = argparse.ArgumentParser.parse_known_args(
  File "/usr/local/lib/python3.8/argparse.py", line 1800, in parse_known_args
    namespace, args = self._parse_known_args(args, namespace)
  File "/usr/local/lib/python3.8/argparse.py", line 2006, in _parse_known_args
    start_index = consume_optional(start_index)
  File "/usr/local/lib/python3.8/argparse.py", line 1946, in consume_optional
    take_action(action, args, option_string)
  File "/usr/local/lib/python3.8/argparse.py", line 1874, in take_action
    action(self, namespace, argument_values, option_string)
  File "/opt/certbot/src/certbot/certbot/_internal/plugins/webroot.py", line 334, in __call__
    namespace.webroot_path.append(_validate_webroot(str(webroot_path)))
  File "/opt/certbot/src/certbot/certbot/_internal/plugins/webroot.py", line 347, in _validate_webroot
    raise errors.PluginError(webroot_path + " does not exist or is not a directory")
certbot.errors.PluginError: /acme-challenge does not exist or is not a directory
2022-07-17 10:41:19,775:ERROR:certbot._internal.log:/acme-challenge does not exist or is not a directory
